<?xml version="1.0" encoding="utf-8"?>
<!-- This URDF was automatically created by SolidWorks to URDF Exporter! Originally created by Stephen Brawner (brawner@gmail.com) 
     Commit Version: 1.6.0-4-g7f85cfe  Build Version: 1.6.7995.38578
     For more information, please see http://wiki.ros.org/sw_urdf_exporter -->
<robot name="hcr">
  <link name="base_footprint"/>
  <link
    name="base_link">
    <inertial>
      <origin
        xyz="-0.024595 0.00063611 0.010099"
        rpy="0 0 0" />
      <mass
        value="0.2386" />
      <inertia
        ixx="0.0023024"
        ixy="4.0374E-06"
        ixz="8.993E-05"
        iyy="0.001616"
        iyz="-1.8423E-06"
        izz="0.0037475" />
    </inertial>
    <visual>
      <origin
        xyz="0 0 0"
        rpy="0 0 0" />
      <geometry>
        <mesh
          filename="file:///$(find hcr_description)/meshes/base_link.STL" />
      </geometry>
      <material
        name="">
        <color
          rgba="0.79216 0.81961 0.93333 1" />
      </material>
    </visual>
    <collision>
      <origin
        xyz="0 0 0"
        rpy="0 0 0" />
      <geometry>
        <mesh
          filename="file:///$(find hcr_description)/meshes/base_link.STL" />
      </geometry>
    </collision>
  </link>
  <joint name="base_joint" type="fixed">
    <parent link="base_footprint"/>
    <child link="base_link"/>
    <origin rpy="0 0 0" xyz="0 0 0.135"/>
  </joint>
  <link
    name="LinkLeft">
    <inertial>
      <origin
        xyz="-2.7756E-15 1.4659E-10 1.7375E-14"
        rpy="0 0 0" />
      <mass
        value="0.37953" />
      <inertia
        ixx="0.00020246"
        ixy="-2.9E-17"
        ixz="3.4286E-17"
        iyy="0.0003853"
        iyz="3.6874E-17"
        izz="0.00020246" />
    </inertial>
    <visual>
      <origin
        xyz="0 0 0"
        rpy="0 0 0" />
      <geometry>
        <mesh
          filename="file:///$(find hcr_description)/meshes/LinkLeft.STL" />
      </geometry>
      <material
        name="">
        <color
          rgba="0.77647 0.75686 0.73725 1" />
      </material>
    </visual>
    <collision>
      <origin
        xyz="0 0 0"
        rpy="0 0 0" />
      <geometry>
        <mesh
          filename="file:///$(find hcr_description)/meshes/LinkLeft.STL" />
      </geometry>
    </collision>
  </link>
  <joint
    name="leftjoint"
    type="continuous">
    <origin
      xyz="-0.069286 0.13393 0.026792"
      rpy="0 0 0" />
    <parent
      link="base_link" />
    <child
      link="LinkLeft" />
    <axis
      xyz="0 1 0" />
  </joint>
  <link
    name="LinkRight">
    <inertial>
      <origin
        xyz="1.46549439250521E-14 1.46593487349023E-10 9.79771819231701E-15"
        rpy="0 0 0" />
      <mass
        value="0.379534844701062" />
      <inertia
        ixx="0.000202456724984576"
        ixy="2.21226724094959E-17"
        ixz="7.92015111702085E-17"
        iyy="0.000385298716133122"
        iyz="4.21440826426833E-17"
        izz="0.000202456724984348" />
    </inertial>
    <visual>
      <origin
        xyz="0 0 0"
        rpy="0 0 0" />
      <geometry>
        <mesh
          filename="file:///$(find hcr_description)/meshes/LinkRight.STL" />
      </geometry>
      <material
        name="">
        <color
          rgba="0.776470588235294 0.756862745098039 0.737254901960784 1" />
      </material>
    </visual>
    <collision>
      <origin
        xyz="0 0 0"
        rpy="0 0 0" />
      <geometry>
        <mesh
          filename="file:///$(find hcr_description)/meshes/LinkRight.STL" />
      </geometry>
    </collision>
  </link>
  <joint
    name="rightjoint"
    type="continuous">
    <origin
      xyz="-0.069286 -0.13107 0.026792"
      rpy="0 0 0" />
    <parent
      link="base_link" />
    <child
      link="LinkRight" />
    <axis
      xyz="0 1 0" />
  </joint>
  <link
    name="TopBase">
    <inertial>
      <origin
        xyz="-7.26514852761317E-06 -0.00189838417120627 0.058141742645062"
        rpy="0 0 0" />
      <mass
        value="0.405244396507155" />
      <inertia
        ixx="0.00517247846818346"
        ixy="9.24430319882831E-07"
        ixz="-5.13991389350515E-08"
        iyy="0.00504424828112145"
        iyz="4.89241500471061E-05"
        izz="0.00957090759837318" />
    </inertial>
    <visual>
      <origin
        xyz="0 0 0"
        rpy="0 0 0" />
      <geometry>
        <mesh
          filename="file:///$(find hcr_description)/meshes/TopBase.STL" />
      </geometry>
      <material
        name="">
        <color
          rgba="0.792156862745098 0.819607843137255 0.933333333333333 1" />
      </material>
    </visual>
    <collision>
      <origin
        xyz="0 0 0"
        rpy="0 0 0" />
      <geometry>
        <mesh
          filename="file:///$(find hcr_description)/meshes/TopBase.STL" />
      </geometry>
    </collision>
  </link>
  <joint
    name="topbase"
    type="fixed">
    <origin
      xyz="-0.0095529 0.00020907 0"
      rpy="0 0 -1.5708" />
    <parent
      link="base_link" />
    <child
      link="TopBase" />
    <axis
      xyz="0 0 0" />
  </joint>
  <link
    name="FrontSensor">
    <inertial>
      <origin
        xyz="0.000219576562031087 -0.000179778747185388 0.000802109957368766"
        rpy="0 0 0" />
      <mass
        value="0.000220261894970756" />
      <inertia
        ixx="3.41447918387968E-09"
        ixy="-1.75581067564551E-10"
        ixz="-2.61441646449792E-11"
        iyy="2.07422938008201E-09"
        iyz="-2.8214482772722E-11"
        izz="5.38151055700922E-09" />
    </inertial>
    <visual>
      <origin
        xyz="0 0 0"
        rpy="0 0 0" />
      <geometry>
        <mesh
          filename="file:///$(find hcr_description)/meshes/FrontSensor.STL" />
      </geometry>
      <material
        name="">
        <color
          rgba="0.792156862745098 0.819607843137255 0.933333333333333 1" />
      </material>
    </visual>
    <collision>
      <origin
        xyz="0 0 0"
        rpy="0 0 0" />
      <geometry>
        <mesh
          filename="file:///$(find hcr_description)/meshes/FrontSensor.STL" />
      </geometry>
    </collision>
  </link>
  <joint
    name="sensorfront"
    type="fixed">
    <origin
      xyz="0.00264999999999826 0.202113784395946 0.0207131649230097"
      rpy="1.57079632679491 0 3.14159265358979" />
    <parent
      link="TopBase" />
    <child
      link="FrontSensor" />
    <axis
      xyz="0 0 0" />
  </joint>
  <link
    name="LeftSensor">
    <inertial>
      <origin
        xyz="1.59732457643558E-05 0.00366778084726835 -7.49171301571983E-05"
        rpy="0 0 0" />
      <mass
        value="0.00401081292145451" />
      <inertia
        ixx="1.13242599869644E-07"
        ixy="3.25699933289137E-14"
        ixz="-3.54101401451094E-14"
        iyy="3.75731975529152E-07"
        iyz="9.43354549507646E-15"
        izz="3.11874315201979E-07" />
    </inertial>
    <visual>
      <origin
        xyz="0 0 0"
        rpy="0 0 0" />
      <geometry>
        <mesh
          filename="file:///$(find hcr_description)/meshes/LeftSensor.STL" />
      </geometry>
      <material
        name="">
        <color
          rgba="0.792156862745098 0.819607843137255 0.933333333333333 1" />
      </material>
    </visual>
    <collision>
      <origin
        xyz="0 0 0"
        rpy="0 0 0" />
      <geometry>
        <mesh
          filename="file:///$(find hcr_description)/meshes/LeftSensor.STL" />
      </geometry>
    </collision>
  </link>
  <joint
    name="sensorleft"
    type="fixed">
    <origin
      xyz="-0.048468609467237 0.178768106046641 0.0202499999999995"
      rpy="0 0 0.651344982786181" />
    <parent
      link="TopBase" />
    <child
      link="LeftSensor" />
    <axis
      xyz="0 0 0" />
  </joint>
  <link
    name="Right Sensor">
    <inertial>
      <origin
        xyz="1.59732623161157E-05 0.00366778084065522 -7.49171448294339E-05"
        rpy="0 0 0" />
      <mass
        value="0.00401081292345283" />
      <inertia
        ixx="1.13242599872581E-07"
        ixy="3.25729124856913E-14"
        ixz="-3.54161355220121E-14"
        iyy="3.75731975536213E-07"
        iyz="9.43995184901037E-15"
        izz="3.11874315207144E-07" />
    </inertial>
    <visual>
      <origin
        xyz="0 0 0"
        rpy="0 0 0" />
      <geometry>
        <mesh
          filename="file:///$(find hcr_description)/meshes/Right Sensor.STL" />
      </geometry>
      <material
        name="">
        <color
          rgba="0.792156862745098 0.819607843137255 0.933333333333333 1" />
      </material>
    </visual>
    <collision>
      <origin
        xyz="0 0 0"
        rpy="0 0 0" />
      <geometry>
        <mesh
          filename="file:///$(find hcr_description)/meshes/Right Sensor.STL" />
      </geometry>
    </collision>
  </link>
  <joint
    name="sensorright"
    type="fixed">
    <origin
      xyz="0.0484684340402228 0.178768239779714 0.0201750003243945"
      rpy="0 0.00588236142210134 -0.651344982786172" />
    <parent
      link="TopBase" />
    <child
      link="Right Sensor" />
    <axis
      xyz="0 0 0" />
  </joint>
  <link
    name="Back Sensor">
    <inertial>
      <origin
        xyz="1.5973240484024E-05 0.00366778081506303 -7.49172293727784E-05"
        rpy="0 0 0" />
      <mass
        value="0.0040108129974793" />
      <inertia
        ixx="1.13242599922043E-07"
        ixy="3.25723592787925E-14"
        ixz="-3.54059421448397E-14"
        iyy="3.75731975485677E-07"
        iyz="9.4388356061855E-15"
        izz="3.11874315114256E-07" />
    </inertial>
    <visual>
      <origin
        xyz="0 0 0"
        rpy="0 0 0" />
      <geometry>
        <mesh
          filename="file:///$(find hcr_description)/meshes/Back Sensor.STL" />
      </geometry>
      <material
        name="">
        <color
          rgba="0.792156862745098 0.819607843137255 0.933333333333333 1" />
      </material>
    </visual>
    <collision>
      <origin
        xyz="0 0 0"
        rpy="0 0 0" />
      <geometry>
        <mesh
          filename="file:///$(find hcr_description)/meshes/Back Sensor.STL" />
      </geometry>
    </collision>
  </link>
  <joint
    name="sensorback"
    type="fixed">
    <origin
      xyz="0 -0.136292231744059 0.0202500000000009"
      rpy="0 0 3.14159265358979" />
    <parent
      link="TopBase" />
    <child
      link="Back Sensor" />
    <axis
      xyz="0 0 0" />
  </joint>
  <link
    name="Roller">
    <inertial>
      <origin
        xyz="-1.56125112837913E-17 0.00392642788355968 0"
        rpy="0 0 0" />
      <mass
        value="0.0024920522859458" />
      <inertia
        ixx="9.99323408278675E-08"
        ixy="-3.14892146581247E-22"
        ixz="4.0793575130789E-23"
        iyy="1.84120231682541E-07"
        iyz="1.25469865294303E-25"
        izz="9.99323408278676E-08" />
    </inertial>
    <visual>
      <origin
        xyz="0 0 0"
        rpy="0 0 0" />
      <geometry>
        <mesh
          filename="file:///$(find hcr_description)/meshes/Roller.STL" />
      </geometry>
      <material
        name="">
        <color
          rgba="0.792156862745098 0.819607843137255 0.933333333333333 1" />
      </material>
    </visual>
    <collision>
      <origin
        xyz="0 0 0"
        rpy="0 0 0" />
      <geometry>
        <mesh
          filename="file:///$(find hcr_description)/meshes/Roller.STL" />
      </geometry>
    </collision>
  </link>
  <joint
    name="rollerfront"
    type="fixed">
    <origin
      xyz="0.17582 0.00020907 -0.0003"
      rpy="-1.5708 0 0" />
    <parent
      link="base_link" />
    <child
      link="Roller" />
    <axis
      xyz="0 0 0" />
  </joint>
  <link
    name="UV">
    <inertial>
      <origin
        xyz="0 0 0"
        rpy="0 0 0" />
      <mass
        value="0" />
      <inertia
        ixx="0"
        ixy="0"
        ixz="0"
        iyy="0"
        iyz="0"
        izz="0" />
    </inertial>
    <visual>
      <origin
        xyz="0 0 0"
        rpy="0 0 0" />
      <geometry>
        <mesh
          filename="file:///$(find hcr_description)/meshes/UV.STL" />
      </geometry>
      <material
        name="">
        <color
          rgba="1 1 1 1" />
      </material>
    </visual>
    <collision>
      <origin
        xyz="0 0 0"
        rpy="0 0 0" />
      <geometry>
        <mesh
          filename="file:///$(find hcr_description)/meshes/UV.STL" />
      </geometry>
    </collision>
  </link>
  <joint
    name="uv"
    type="fixed">
    <origin
      xyz="-0.00955294851552965 0.000209074196459991 0.0880000000000047"
      rpy="0 0 1.5707963267949" />
    <parent
      link="base_link" />
    <child
      link="UV" />
    <axis
      xyz="0 0 0" />
  </joint>

  <gazebo>
    <plugin filename="libgazebo_ros_diff_drive.so" name="gazebo_base_controller">
      <odometry_frame>odom</odometry_frame>
      <commandTopic>cmd_vel</commandTopic>
      <publish_odom>true</publish_odom>
      <publish_odom_tf>true</publish_odom_tf>
      <!-- <publish_wheel_tf>false</publish_wheel_tf> -->
      <update_rate>15.0</update_rate>
      <left_joint>leftjoint</left_joint>
      <right_joint>rightjoint</right_joint>
      <wheel_separation>0.5</wheel_separation>
      <wheel_diameter>0.3</wheel_diameter>
      <max_wheel_acceleration>0.7</max_wheel_acceleration>
      <max_wheel_torque>8</max_wheel_torque>
      <robotBaseFrame>base_link</robotBaseFrame>

    </plugin>
  </gazebo>

<gazebo reference="base_link">
  <material>Gazebo/Orange</material>
</gazebo>

<gazebo reference="LinkLeft">
  <material>Gazebo/Black</material>
</gazebo>

<gazebo reference="LinkRight">
  <material>Gazebo/Black</material>
</gazebo>

<gazebo reference="TopBase">
  <material>Gazebo/Gray</material>
</gazebo>

<gazebo reference="Roller">
  <material>Gazebo/Black</material>
</gazebo>

<gazebo reference="UV">
  <material>Gazebo/Blue</material>
</gazebo>

<link name="lidar">
    <inertial>
            <mass value="0.005" />
            <inertia ixx="0.01" ixy="0.0" ixz="0" 
            iyy="0.01" iyz="0" izz="0.01" />
    </inertial>

    <visual>
      
      <geometry>
        <cylinder radius="0.025" length="0.025"/>
      </geometry>
      <material name="white">
        <color rgba="1 1 1 1"/>
      </material>
    </visual>

    <collision>
      <geometry>
          <box size="0.025 0.025 0.025"/>
      </geometry>
    </collision>
  </link>

  <joint name="lidar_joint" type="fixed">
    <origin xyz="0.09 0 0.09" rpy="0 0 0"/>
    <parent link="base_link"/>
    <child link="lidar"/>
    <axis xyz="0.0 0.0 1.0"/>

  </joint>


<gazebo reference="lidar">
    <sensor type="gpu_ray" name="head_lidar_sensor">
      <pose>0 0 0 0 0 0</pose>
      <visualize>true</visualize>
      <update_rate>40</update_rate>
      <ray>
        <scan>
          <horizontal>
            <samples>720</samples>
            <resolution>1</resolution>
            <min_angle>-1.570796</min_angle>
            <max_angle>1.570796</max_angle>
          </horizontal>
        </scan>
        <range>
          <min>0.10</min>
          <max>10.0</max>
          <resolution>0.01</resolution>
        </range>
        <noise>
          <type>gaussian</type>
          <!-- Noise parameters based on published spec for Hokuyo laser
               achieving "+-30mm" accuracy at range < 10m.  A mean of 0.0m and
               stddev of 0.01m will put 99.7% of samples within 0.03m of the true
               reading. -->
          <mean>0.0</mean>
          <stddev>0.01</stddev>
        </noise>
      </ray>
      <plugin name="gazebo_ros_lidar_controller" filename="libgazebo_ros_ray_sensor.so">
        <topicName>/hcr/laser/scan</topicName>
        <frameName>lidar</frameName>
      </plugin>
    </sensor>
  </gazebo>

  <link name="imu_link">

  <inertial>
            <mass value="0.005" />
            <inertia ixx="0.01" ixy="0.0" ixz="0" 
            iyy="0.01" iyz="0" izz="0.01" />
    </inertial>
  <visual>
    <geometry>
      <box size="0.01 0.01 0.01"/>
    </geometry>
  </visual>

  <collision>
    <geometry>
      <box size="0.01 0.01 0.01"/>
    </geometry>
  </collision>

  
</link>

<joint name="imu_joint" type="fixed">
  <parent link="base_link"/>
  <child link="imu_link"/>
  <origin xyz="0 0 0.01"/>
</joint>

 <gazebo reference="imu_link">
  <sensor name="imu_sensor" type="imu">
   <plugin filename="libgazebo_ros_imu_sensor.so" name="imu_plugin">
      <ros>
        <!--namespace>/hcr</namespace-->
        <remapping>~/out:=imu</remapping>
      </ros>
      <initial_orientation_as_reference>false</initial_orientation_as_reference>
    </plugin>
    <always_on>true</always_on>
    <update_rate>100</update_rate>
    <visualize>true</visualize>
    <imu>
      <angular_velocity>
        <x>
          <noise type="gaussian">
            <mean>0.0</mean>
            <stddev>2e-4</stddev>
            <bias_mean>0.0000075</bias_mean>
            <bias_stddev>0.0000008</bias_stddev>
          </noise>
        </x>
        <y>
          <noise type="gaussian">
            <mean>0.0</mean>
            <stddev>2e-4</stddev>
            <bias_mean>0.0000075</bias_mean>
            <bias_stddev>0.0000008</bias_stddev>
          </noise>
        </y>
        <z>
          <noise type="gaussian">
            <mean>0.0</mean>
            <stddev>2e-4</stddev>
            <bias_mean>0.0000075</bias_mean>
            <bias_stddev>0.0000008</bias_stddev>
          </noise>
        </z>
      </angular_velocity>
      <linear_acceleration>
        <x>
          <noise type="gaussian">
            <mean>0.0</mean>
            <stddev>1.7e-2</stddev>
            <bias_mean>0.1</bias_mean>
            <bias_stddev>0.001</bias_stddev>
          </noise>
        </x>
        <y>
          <noise type="gaussian">
            <mean>0.0</mean>
            <stddev>1.7e-2</stddev>
            <bias_mean>0.1</bias_mean>
            <bias_stddev>0.001</bias_stddev>
          </noise>
        </y>
        <z>
          <noise type="gaussian">
            <mean>0.0</mean>
            <stddev>1.7e-2</stddev>
            <bias_mean>0.1</bias_mean>
            <bias_stddev>0.001</bias_stddev>
          </noise>
        </z>
      </linear_acceleration>
    </imu>
  </sensor>
</gazebo>


  
</robot>