<?xml version="1.0" ?>
<!-- This URDF was automatically created by SolidWorks to URDF Exporter! Originally created by Stephen Brawner (brawner@gmail.com) 
     Commit Version: 1.6.0-4-g7f85cfe  Build Version: 1.6.7995.38578
     For more information, please see http://wiki.ros.org/sw_urdf_exporter -->
<robot name="hcr">
  <link
    name="base_link">
    <inertial>
      <origin
        xyz="0.272181582028018 0.159269166288147 -0.214076713479967"
        rpy="0 0 0" />
      <mass
        value="0.238604296907217" />
      <inertia
        ixx="0.00161602401364483"
        ixy="-1.84233988198401E-06"
        ixz="4.03736610228801E-06"
        iyy="0.00374746677459711"
        iyz="8.99304562369235E-05"
        izz="0.00230237339404268" />
    </inertial>
    <visual>
      <origin
        xyz="0 0 0"
        rpy="0 0 0" />
      <geometry>
        <mesh
          filename="file:///$(find hcr_description)/meshes/base_link.STL" />
      </geometry>
      <material
        name="">
        <color
          rgba="0.792156862745098 0.819607843137255 0.933333333333333 1" />
      </material>
    </visual>
    <collision>
      <origin
        xyz="0 0 0"
        rpy="0 0 0" />
      <geometry>
        <mesh
          filename="file:///$(find hcr_description)/meshes/base_link.STL" />
      </geometry>
    </collision>
  </link>
  <link
    name="LinkLeft">
    <inertial>
      <origin
        xyz="-2.83106871279415E-15 1.46593459593447E-10 1.7430501486615E-14"
        rpy="0 0 0" />
      <mass
        value="0.379534844701067" />
      <inertia
        ixx="0.000202456724984328"
        ixy="-2.90089588535188E-17"
        ixz="3.42712764498833E-17"
        iyy="0.000385298716133126"
        iyz="3.6870366115527E-17"
        izz="0.0002024567249846" />
    </inertial>
    <visual>
      <origin
        xyz="0 0 0"
        rpy="0 0 0" />
      <geometry>
        <mesh
          filename="file:///$(find hcr_description)/meshes/LinkLeft.STL" />
      </geometry>
      <material
        name="">
        <color
          rgba="0.776470588235294 0.756862745098039 0.737254901960784 1" />
      </material>
    </visual>
    <collision>
      <origin
        xyz="0 0 0"
        rpy="0 0 0" />
      <geometry>
        <mesh
          filename="file:///$(find hcr_description)/meshes/LinkLeft.STL" />
      </geometry>
    </collision>
  </link>
  <joint
    name="leftjoint"
    type="continuous">
    <origin
      xyz="0.40548 0.25877 0.17596"
      rpy="0 0 -1.5708" />
    <parent
      link="base_link" />
    <child
      link="LinkLeft" />
    <axis
      xyz="0 1 0" />
    <limit
      effort="1"
      velocity="1" />
  </joint>
  <link
    name="LinkRight">
    <inertial>
      <origin
        xyz="1.46549439250521E-14 1.46593487349023E-10 9.79771819231701E-15"
        rpy="0 0 0" />
      <mass
        value="0.379534844701062" />
      <inertia
        ixx="0.000202456724984576"
        ixy="2.21258446150424E-17"
        ixz="7.92052711665349E-17"
        iyy="0.000385298716133122"
        iyz="4.21419864991452E-17"
        izz="0.000202456724984348" />
    </inertial>
    <visual>
      <origin
        xyz="0 0 0"
        rpy="0 0 0" />
      <geometry>
        <mesh
          filename="file:///$(find hcr_description)/meshes/LinkRight.STL" />
      </geometry>
      <material
        name="">
        <color
          rgba="0.776470588235294 0.756862745098039 0.737254901960784 1" />
      </material>
    </visual>
    <collision>
      <origin
        xyz="0 0 0"
        rpy="0 0 0" />
      <geometry>
        <mesh
          filename="file:///$(find hcr_description)/meshes/LinkRight.STL" />
      </geometry>
    </collision>
  </link>
  <joint
    name="rightjoint"
    type="continuous">
    <origin
      xyz="0.14048 0.25877 0.17596"
      rpy="0 0 -1.5708" />
    <parent
      link="base_link" />
    <child
      link="LinkRight" />
    <axis
      xyz="0 1 0" />
    <limit
      effort="1"
      velocity="1" />
  </joint>
  <link
    name="TopBase">
    <inertial>
      <origin
        xyz="-7.26514852711357E-06 -0.00189838417120639 0.0581417426450621"
        rpy="0 0 0" />
      <mass
        value="0.405244396507161" />
      <inertia
        ixx="0.00517247846865477"
        ixy="9.24430384033536E-07"
        ixz="-5.13991389366313E-08"
        iyy="0.00504424828111493"
        iyz="4.89241500471395E-05"
        izz="0.00957090759883802" />
    </inertial>
    <visual>
      <origin
        xyz="0 0 0"
        rpy="0 0 0" />
      <geometry>
        <mesh
          filename="file:///$(find hcr_description)/meshes/TopBase.STL" />
      </geometry>
      <material
        name="">
        <color
          rgba="0.792156862745098 0.819607843137255 0.933333333333333 1" />
      </material>
    </visual>
    <collision>
      <origin
        xyz="0 0 0"
        rpy="0 0 0" />
      <geometry>
        <mesh
          filename="file:///$(find hcr_description)/meshes/TopBase.STL" />
      </geometry>
    </collision>
  </link>
  <joint
    name="topbase"
    type="fixed">
    <origin
      xyz="0.271754547099807 0.199034844261066 0.149170531176844"
      rpy="0 0 3.14159265358979" />
    <parent
      link="base_link" />
    <child
      link="TopBase" />
    <axis
      xyz="0 0 0" />
  </joint>
  <link
    name="FrontSensor">
    <inertial>
      <origin
        xyz="0.00021957656203081 -0.000179778747185139 0.000802109957368631"
        rpy="0 0 0" />
      <mass
        value="0.000220261894970755" />
      <inertia
        ixx="3.41447918387967E-09"
        ixy="-1.75581067564555E-10"
        ixz="-2.61441646449781E-11"
        iyy="2.074229380082E-09"
        iyz="-2.82144827727232E-11"
        izz="5.3815105570092E-09" />
    </inertial>
    <visual>
      <origin
        xyz="0 0 0"
        rpy="0 0 0" />
      <geometry>
        <mesh
          filename="file:///$(find hcr_description)/meshes/FrontSensor.STL" />
      </geometry>
      <material
        name="">
        <color
          rgba="0.792156862745098 0.819607843137255 0.933333333333333 1" />
      </material>
    </visual>
    <collision>
      <origin
        xyz="0 0 0"
        rpy="0 0 0" />
      <geometry>
        <mesh
          filename="file:///$(find hcr_description)/meshes/FrontSensor.STL" />
      </geometry>
    </collision>
  </link>
  <joint
    name="sensorfront"
    type="fixed">
    <origin
      xyz="0.00265 0.20211 0.020713"
      rpy="1.5708 0 3.1416" />
    <parent
      link="TopBase" />
    <child
      link="FrontSensor" />
    <axis
      xyz="0 0 0" />
  </joint>
  <link
    name="LeftSensor">
    <inertial>
      <origin
        xyz="1.59732457644113E-05 0.00366778084726832 -7.49171301575036E-05"
        rpy="0 0 0" />
      <mass
        value="0.0040108129214545" />
      <inertia
        ixx="1.13242599869644E-07"
        ixy="3.25699932395782E-14"
        ixz="-3.54101401644334E-14"
        iyy="3.75731975529152E-07"
        iyz="9.43354550518283E-15"
        izz="3.11874315201979E-07" />
    </inertial>
    <visual>
      <origin
        xyz="0 0 0"
        rpy="0 0 0" />
      <geometry>
        <mesh
          filename="file:///$(find hcr_description)/meshes/LeftSensor.STL" />
      </geometry>
      <material
        name="">
        <color
          rgba="0.792156862745098 0.819607843137255 0.933333333333333 1" />
      </material>
    </visual>
    <collision>
      <origin
        xyz="0 0 0"
        rpy="0 0 0" />
      <geometry>
        <mesh
          filename="file:///$(find hcr_description)/meshes/LeftSensor.STL" />
      </geometry>
    </collision>
  </link>
  <joint
    name="sensorleft"
    type="fixed">
    <origin
      xyz="-0.048469 0.17877 0.02025"
      rpy="0 0 0.65134" />
    <parent
      link="TopBase" />
    <child
      link="LeftSensor" />
    <axis
      xyz="0 0 0" />
  </joint>
  <link
    name="Right Sensor">
    <inertial>
      <origin
        xyz="1.59732623157272E-05 0.00366778084065505 -7.4917144829767E-05"
        rpy="0 0 0" />
      <mass
        value="0.00401081292345314" />
      <inertia
        ixx="1.13242599872581E-07"
        ixy="3.25729119000475E-14"
        ixz="-3.54161355195564E-14"
        iyy="3.75731975536213E-07"
        iyz="9.4399518434269E-15"
        izz="3.11874315207144E-07" />
    </inertial>
    <visual>
      <origin
        xyz="0 0 0"
        rpy="0 0 0" />
      <geometry>
        <mesh
          filename="file:///$(find hcr_description)/meshes/Right Sensor.STL" />
      </geometry>
      <material
        name="">
        <color
          rgba="0.792156862745098 0.819607843137255 0.933333333333333 1" />
      </material>
    </visual>
    <collision>
      <origin
        xyz="0 0 0"
        rpy="0 0 0" />
      <geometry>
        <mesh
          filename="file:///$(find hcr_description)/meshes/Right Sensor.STL" />
      </geometry>
    </collision>
  </link>
  <joint
    name="sensorright"
    type="fixed">
    <origin
      xyz="0.048468 0.17877 0.020175"
      rpy="0 0.0058824 -0.65134" />
    <parent
      link="TopBase" />
    <child
      link="Right Sensor" />
    <axis
      xyz="0 0 0" />
  </joint>
  <link
    name="Back Sensor">
    <inertial>
      <origin
        xyz="1.59732411140201E-05 0.00366778081525609 -7.49172286142741E-05"
        rpy="0 0 0" />
      <mass
        value="0.00401081299707549" />
      <inertia
        ixx="1.13242599922018E-07"
        ixy="3.25723280523753E-14"
        ixz="-3.54059303020558E-14"
        iyy="3.75731975485628E-07"
        iyz="9.43882406426771E-15"
        izz="3.11874315114205E-07" />
    </inertial>
    <visual>
      <origin
        xyz="0 0 0"
        rpy="0 0 0" />
      <geometry>
        <mesh
          filename="file:///$(find hcr_description)/meshes/Back Sensor.STL" />
      </geometry>
      <material
        name="">
        <color
          rgba="0.792156862745098 0.819607843137255 0.933333333333333 1" />
      </material>
    </visual>
    <collision>
      <origin
        xyz="0 0 0"
        rpy="0 0 0" />
      <geometry>
        <mesh
          filename="file:///$(find hcr_description)/meshes/Back Sensor.STL" />
      </geometry>
    </collision>
  </link>
  <joint
    name="sensorback"
    type="fixed">
    <origin
      xyz="0 -0.13629 0.02025"
      rpy="0 0 3.1416" />
    <parent
      link="TopBase" />
    <child
      link="Back Sensor" />
    <axis
      xyz="0 0 0" />
  </joint>
</robot>